Workbook

Sheet Sheet2

Sheet Sheet3
A3: Row Labels | B3: Count of Company
A4: Accenture | B4: 2
A5: Amazon | B5: 2
A6: Capgemini | B6: 2
A7: Google | B7: 2
A8: HCL | B8: 1
A9: Infosys | B9: 4
A10: L&T | B10: 2
A11: Microsoft | B11: 2
A12: None | B12: 7
A13: Tata Motors | B13: 1
A14: TCS | B14: 3
A15: Wipro | B15: 2
A16: Grand Total | B16: 30

Sheet Sheet4
A3: Row Labels | B3: Average of Salary_LPA
A4: CIVIL | B4: 0
A5: CSE | B5: 11
A6: ECE | B6: 3.0857143
A7: IT | B7: 6.1857143
A8: MECH | B8: 3.3
A9: Grand Total | B9: 5.9033333

Sheet Sheet5

Sheet Sheet6
A3: Row Labels | B3: Count of Student_Name
A4: 0-5 | B4: 5
A5: 10+ | B5: 6
A6: 5-10 | B6: 12
A7: Unplaced | B7: 7
A8: (blank)
A9: Grand Total | B9: 30

Sheet placement
A1: Student_Name | B1: Department | C1: CGPA | D1: Placed | E1: Salary_LPA | F1: Company | G1: salary range | I1: TOTAL | J1: 30
A2: Arun | B2: CSE | C2: 8.5 | D2: Yes | E2: 6.5 | F2: TCS | G2: =IF(E2=0,"Unplaced",IF(E2<=5,"0-5",IF(E2<=10,"5-10","10+"))) -> 5-10 | I2: PLACED | J2: 23
A3: Meera | B3: IT | C3: 7.8 | D3: Yes | E3: 5.2 | F3: Infosys | G3: =IF(E3=0,"Unplaced",IF(E3<=5,"0-5",IF(E3<=10,"5-10","10+"))) -> 5-10 | I3: UNPLACED | J3: 7
A4: Rahul | B4: ECE | C4: 6.9 | D4: No | E4: 0 | F4: None | G4: =IF(E4=0,"Unplaced",IF(E4<=5,"0-5",IF(E4<=10,"5-10","10+"))) -> Unplaced
A5: Sneha | B5: CSE | C5: 9.1 | D5: Yes | E5: 12 | F5: Amazon | G5: =IF(E5=0,"Unplaced",IF(E5<=5,"0-5",IF(E5<=10,"5-10","10+"))) -> 10+
A6: Vijay | B6: MECH | C6: 7.2 | D6: Yes | E6: 4 | F6: L&T | G6: =IF(E6=0,"Unplaced",IF(E6<=5,"0-5",IF(E6<=10,"5-10","10+"))) -> 0-5
A7: Anjali | B7: CSE | C7: 8.8 | D7: Yes | E7: 10.5 | F7: Google | G7: =IF(E7=0,"Unplaced",IF(E7<=5,"0-5",IF(E7<=10,"5-10","10+"))) -> 10+
A8: Kiran | B8: ECE | C8: 6.5 | D8: No | E8: 0 | F8: None | G8: =IF(E8=0,"Unplaced",IF(E8<=5,"0-5",IF(E8<=10,"5-10","10+"))) -> Unplaced
A9: Divya | B9: IT | C9: 7.9 | D9: Yes | E9: 5.8 | F9: Wipro | G9: =IF(E9=0,"Unplaced",IF(E9<=5,"0-5",IF(E9<=10,"5-10","10+"))) -> 5-10
A10: Ravi | B10: CIVIL | C10: 6.8 | D10: No | E10: 0 | F10: None | G10: =IF(E10=0,"Unplaced",IF(E10<=5,"0-5",IF(E10<=10,"5-10","10+"))) -> Unplaced
A11: Pooja | B11: CSE | C11: 9.3 | D11: Yes | E11: 14 | F11: Microsoft | G11: =IF(E11=0,"Unplaced",IF(E11<=5,"0-5",IF(E11<=10,"5-10","10+"))) -> 10+
A12: Suresh | B12: MECH | C12: 7.5 | D12: Yes | E12: 4.5 | F12: Tata Motors | G12: =IF(E12=0,"Unplaced",IF(E12<=5,"0-5",IF(E12<=10,"5-10","10+"))) -> 0-5
A13: Neha | B13: ECE | C13: 8 | D13: Yes | E13: 6 | F13: Capgemini | G13: =IF(E13=0,"Unplaced",IF(E13<=5,"0-5",IF(E13<=10,"5-10","10+"))) -> 5-10
A14: Ajay | B14: CSE | C14: 8.2 | D14: Yes | E14: 7 | F14: Accenture | G14: =IF(E14=0,"Unplaced",IF(E14<=5,"0-5",IF(E14<=10,"5-10","10+"))) -> 5-10
A15: Kavya | B15: IT | C15: 7.1 | D15: Yes | E15: 4.8 | F15: Infosys | G15: =IF(E15=0,"Unplaced",IF(E15<=5,"0-5",IF(E15<=10,"5-10","10+"))) -> 0-5
... A31: Bhavana | B31: IT | C31: 8.4 | D31: Yes | E31: 7 | F31: Infosys | G31: =IF(E31=0,"Unplaced",IF(E31<=5,"0-5",IF(E31<=10,"5-10","10+"))) -> 5-10
E35: PLACEMENT BY DEPARTMENT
G40: Row Labels | H40: Count of Placed
G41: CIVIL | H41: 3
G42: CSE | H42: 9
G43: ECE | H43: 7
G44: IT | H44: 7
G45: MECH | H45: 4
G46: Grand Total | H46: 30
A65: PLACED AND UNPLACED
B89: SALARY DISTRIBUTION
G93: Row Labels | H93: Count of Student_Name
G94: 0-5 | H94: 5
G95: 10+ | H95: 6
G96: 5-10 | H96: 12
G97: Unplaced | H97: 7
G98: (blank)
G99: Grand Total | H99: 30
C119: CGPA VS SALARY
G123: CGPA | H123: Salary_LPA
G124: 8.5 | H124: 6.5
G125: 7.8 | H125: 5.2
G126: 6.9 | H126: 0
G127: 9.1 | H127: 12
G128: 7.2 | H128: 4
...

Sheet Sheet1
A1: PLACEMENT ANALYSIS DASHBOARD
A4: TOTAL STUDENT | D4: PLACED STUDENTS | G4: UNPLACED STUDENTS | J4: AVERAGE SALARY | M4: HIGHEST SALARY | P4: PLACEMENT PERCENTAGE
A5: =COUNTA(placement!A2:A31) -> 30 | D5: =COUNTIF(placement!D2:D31,"yes") -> 23 | G5: =COUNTIF(placement!D2:D31,"no") -> 7 | J5: =AVERAGEIF(placement!E2:E31,">0") -> 7.7 | M5: =MAX(placement!E2:E31) -> 15 | P5: =ROUND(COUNTIF(placement!D2:D31,"Yes")/COUNTA(placement!A2:A31)*100,2)&"%" -> 76.67%
